Exception on /send/email/password [POST]
Traceback (most recent call last):
  File "/home/cashcaruser21/CashCar/flaskenv/lib/python3.6/site-packages/flask/app.py", line 2447, in wsgi_app
    response = self.full_dispatch_request()
  File "/home/cashcaruser21/CashCar/flaskenv/lib/python3.6/site-packages/flask/app.py", line 1952, in full_dispatch_request
    rv = self.handle_user_exception(e)
  File "/home/cashcaruser21/CashCar/flaskenv/lib/python3.6/site-packages/flask_cors/extension.py", line 165, in wrapped_function
    return cors_after_request(app.make_response(f(*args, **kwargs)))
  File "/home/cashcaruser21/CashCar/flaskenv/lib/python3.6/site-packages/flask/app.py", line 1821, in handle_user_exception
    reraise(exc_type, exc_value, tb)
  File "/home/cashcaruser21/CashCar/flaskenv/lib/python3.6/site-packages/flask/_compat.py", line 39, in reraise
    raise value
  File "/home/cashcaruser21/CashCar/flaskenv/lib/python3.6/site-packages/flask/app.py", line 1950, in full_dispatch_request
    rv = self.dispatch_request()
  File "/home/cashcaruser21/CashCar/flaskenv/lib/python3.6/site-packages/flask/app.py", line 1936, in dispatch_request
    return self.view_functions[rule.endpoint](**req.view_args)
  File "./routes.py", line 242, in send_to_client_for_password
    mail.send(msg)
  File "/home/cashcaruser21/CashCar/flaskenv/lib/python3.6/site-packages/flask_mail.py", line 491, in send
    with self.connect() as connection:
  File "/home/cashcaruser21/CashCar/flaskenv/lib/python3.6/site-packages/flask_mail.py", line 144, in __enter__
    self.host = self.configure_host()
  File "/home/cashcaruser21/CashCar/flaskenv/lib/python3.6/site-packages/flask_mail.py", line 165, in configure_host
    host.login(self.mail.username, self.mail.password)
  File "/usr/lib64/python3.6/smtplib.py", line 730, in login
    raise last_exception
  File "/usr/lib64/python3.6/smtplib.py", line 721, in login
    initial_response_ok=initial_response_ok)
  File "/usr/lib64/python3.6/smtplib.py", line 642, in auth
    raise SMTPAuthenticationError(code, resp)
smtplib.SMTPAuthenticationError: (535, b'5.7.8 Username and Password not accepted. Learn more at\n5.7.8  https://support.google.com/mail/?p=BadCredentials a129sm13322864pfa.36 - gsmtp')
Exception on /send/email/password [POST]
Traceback (most recent call last):
  File "/home/cashcaruser21/CashCar/flaskenv/lib/python3.6/site-packages/flask/app.py", line 2447, in wsgi_app
    response = self.full_dispatch_request()
  File "/home/cashcaruser21/CashCar/flaskenv/lib/python3.6/site-packages/flask/app.py", line 1952, in full_dispatch_request
    rv = self.handle_user_exception(e)
  File "/home/cashcaruser21/CashCar/flaskenv/lib/python3.6/site-packages/flask_cors/extension.py", line 165, in wrapped_function
    return cors_after_request(app.make_response(f(*args, **kwargs)))
  File "/home/cashcaruser21/CashCar/flaskenv/lib/python3.6/site-packages/flask/app.py", line 1821, in handle_user_exception
    reraise(exc_type, exc_value, tb)
  File "/home/cashcaruser21/CashCar/flaskenv/lib/python3.6/site-packages/flask/_compat.py", line 39, in reraise
    raise value
  File "/home/cashcaruser21/CashCar/flaskenv/lib/python3.6/site-packages/flask/app.py", line 1950, in full_dispatch_request
    rv = self.dispatch_request()
  File "/home/cashcaruser21/CashCar/flaskenv/lib/python3.6/site-packages/flask/app.py", line 1936, in dispatch_request
    return self.view_functions[rule.endpoint](**req.view_args)
  File "./routes.py", line 242, in send_to_client_for_password
    mail.send(msg)
  File "/home/cashcaruser21/CashCar/flaskenv/lib/python3.6/site-packages/flask_mail.py", line 491, in send
    with self.connect() as connection:
  File "/home/cashcaruser21/CashCar/flaskenv/lib/python3.6/site-packages/flask_mail.py", line 144, in __enter__
    self.host = self.configure_host()
  File "/home/cashcaruser21/CashCar/flaskenv/lib/python3.6/site-packages/flask_mail.py", line 165, in configure_host
    host.login(self.mail.username, self.mail.password)
  File "/usr/lib64/python3.6/smtplib.py", line 730, in login
    raise last_exception
  File "/usr/lib64/python3.6/smtplib.py", line 721, in login
    initial_response_ok=initial_response_ok)
  File "/usr/lib64/python3.6/smtplib.py", line 642, in auth
    raise SMTPAuthenticationError(code, resp)
smtplib.SMTPAuthenticationError: (535, b'5.7.8 Username and Password not accepted. Learn more at\n5.7.8  https://support.google.com/mail/?p=BadCredentials k15sm13174956pfi.0 - gsmtp')
Exception on /send/email/password [POST]
Traceback (most recent call last):
  File "/home/cashcaruser21/CashCar/flaskenv/lib/python3.6/site-packages/flask/app.py", line 2447, in wsgi_app
    response = self.full_dispatch_request()
  File "/home/cashcaruser21/CashCar/flaskenv/lib/python3.6/site-packages/flask/app.py", line 1952, in full_dispatch_request
    rv = self.handle_user_exception(e)
  File "/home/cashcaruser21/CashCar/flaskenv/lib/python3.6/site-packages/flask_cors/extension.py", line 165, in wrapped_function
    return cors_after_request(app.make_response(f(*args, **kwargs)))
  File "/home/cashcaruser21/CashCar/flaskenv/lib/python3.6/site-packages/flask/app.py", line 1821, in handle_user_exception
    reraise(exc_type, exc_value, tb)
  File "/home/cashcaruser21/CashCar/flaskenv/lib/python3.6/site-packages/flask/_compat.py", line 39, in reraise
    raise value
  File "/home/cashcaruser21/CashCar/flaskenv/lib/python3.6/site-packages/flask/app.py", line 1950, in full_dispatch_request
    rv = self.dispatch_request()
  File "/home/cashcaruser21/CashCar/flaskenv/lib/python3.6/site-packages/flask/app.py", line 1936, in dispatch_request
    return self.view_functions[rule.endpoint](**req.view_args)
  File "./routes.py", line 242, in send_to_client_for_password
    mail.send(msg)
  File "/home/cashcaruser21/CashCar/flaskenv/lib/python3.6/site-packages/flask_mail.py", line 491, in send
    with self.connect() as connection:
  File "/home/cashcaruser21/CashCar/flaskenv/lib/python3.6/site-packages/flask_mail.py", line 144, in __enter__
    self.host = self.configure_host()
  File "/home/cashcaruser21/CashCar/flaskenv/lib/python3.6/site-packages/flask_mail.py", line 165, in configure_host
    host.login(self.mail.username, self.mail.password)
  File "/usr/lib64/python3.6/smtplib.py", line 730, in login
    raise last_exception
  File "/usr/lib64/python3.6/smtplib.py", line 721, in login
    initial_response_ok=initial_response_ok)
  File "/usr/lib64/python3.6/smtplib.py", line 642, in auth
    raise SMTPAuthenticationError(code, resp)
smtplib.SMTPAuthenticationError: (535, b'5.7.8 Username and Password not accepted. Learn more at\n5.7.8  https://support.google.com/mail/?p=BadCredentials t14sm12045596pfg.168 - gsmtp')
Exception on /send/email/password [POST]
Traceback (most recent call last):
  File "/home/cashcaruser21/CashCar/flaskenv/lib/python3.6/site-packages/flask/app.py", line 2447, in wsgi_app
    response = self.full_dispatch_request()
  File "/home/cashcaruser21/CashCar/flaskenv/lib/python3.6/site-packages/flask/app.py", line 1952, in full_dispatch_request
    rv = self.handle_user_exception(e)
  File "/home/cashcaruser21/CashCar/flaskenv/lib/python3.6/site-packages/flask_cors/extension.py", line 165, in wrapped_function
    return cors_after_request(app.make_response(f(*args, **kwargs)))
  File "/home/cashcaruser21/CashCar/flaskenv/lib/python3.6/site-packages/flask/app.py", line 1821, in handle_user_exception
    reraise(exc_type, exc_value, tb)
  File "/home/cashcaruser21/CashCar/flaskenv/lib/python3.6/site-packages/flask/_compat.py", line 39, in reraise
    raise value
  File "/home/cashcaruser21/CashCar/flaskenv/lib/python3.6/site-packages/flask/app.py", line 1950, in full_dispatch_request
    rv = self.dispatch_request()
  File "/home/cashcaruser21/CashCar/flaskenv/lib/python3.6/site-packages/flask/app.py", line 1936, in dispatch_request
    return self.view_functions[rule.endpoint](**req.view_args)
  File "/home/cashcaruser21/CashCar/flaskenv/lib/python3.6/site-packages/flasgger/utils.py", line 273, in wrapper
    return function(*args, **kwargs)
  File "./routes.py", line 244, in send_to_client_for_password
    mail.send(msg)
  File "/home/cashcaruser21/CashCar/flaskenv/lib/python3.6/site-packages/flask_mail.py", line 491, in send
    with self.connect() as connection:
  File "/home/cashcaruser21/CashCar/flaskenv/lib/python3.6/site-packages/flask_mail.py", line 144, in __enter__
    self.host = self.configure_host()
  File "/home/cashcaruser21/CashCar/flaskenv/lib/python3.6/site-packages/flask_mail.py", line 165, in configure_host
    host.login(self.mail.username, self.mail.password)
  File "/usr/lib64/python3.6/smtplib.py", line 730, in login
    raise last_exception
  File "/usr/lib64/python3.6/smtplib.py", line 721, in login
    initial_response_ok=initial_response_ok)
  File "/usr/lib64/python3.6/smtplib.py", line 642, in auth
    raise SMTPAuthenticationError(code, resp)
smtplib.SMTPAuthenticationError: (534, b'5.7.14 <https://accounts.google.com/signin/continue?sarp=1&scc=1&plt=AKgnsbu\n5.7.14 aL_IYctVb0KvrjWGmqpzdXiVFaFtot8e3Wgo9ff2J4dhqRDh7KxivJPlkiavQzXYWSGbX\n5.7.14 TGx0IOMZI2_qmt2wYq4Jh2Bc9NHQAj8dtBuHsWLT1LiswyXOGDRESVTzLaTZOdC1>\n5.7.14 Please log in via your web browser and then try again.\n5.7.14  Learn more at\n5.7.14  https://support.google.com/mail/answer/78754 i126sm12542837pfc.20 - gsmtp')
Exception on /send/email/password [POST]
Traceback (most recent call last):
  File "/home/cashcaruser21/CashCar/flaskenv/lib/python3.6/site-packages/flask/app.py", line 2447, in wsgi_app
    response = self.full_dispatch_request()
  File "/home/cashcaruser21/CashCar/flaskenv/lib/python3.6/site-packages/flask/app.py", line 1952, in full_dispatch_request
    rv = self.handle_user_exception(e)
  File "/home/cashcaruser21/CashCar/flaskenv/lib/python3.6/site-packages/flask_cors/extension.py", line 165, in wrapped_function
    return cors_after_request(app.make_response(f(*args, **kwargs)))
  File "/home/cashcaruser21/CashCar/flaskenv/lib/python3.6/site-packages/flask/app.py", line 1821, in handle_user_exception
    reraise(exc_type, exc_value, tb)
  File "/home/cashcaruser21/CashCar/flaskenv/lib/python3.6/site-packages/flask/_compat.py", line 39, in reraise
    raise value
  File "/home/cashcaruser21/CashCar/flaskenv/lib/python3.6/site-packages/flask/app.py", line 1950, in full_dispatch_request
    rv = self.dispatch_request()
  File "/home/cashcaruser21/CashCar/flaskenv/lib/python3.6/site-packages/flask/app.py", line 1936, in dispatch_request
    return self.view_functions[rule.endpoint](**req.view_args)
  File "/home/cashcaruser21/CashCar/flaskenv/lib/python3.6/site-packages/flasgger/utils.py", line 273, in wrapper
    return function(*args, **kwargs)
  File "./routes.py", line 244, in send_to_client_for_password
    mail.send(msg)
  File "/home/cashcaruser21/CashCar/flaskenv/lib/python3.6/site-packages/flask_mail.py", line 491, in send
    with self.connect() as connection:
  File "/home/cashcaruser21/CashCar/flaskenv/lib/python3.6/site-packages/flask_mail.py", line 144, in __enter__
    self.host = self.configure_host()
  File "/home/cashcaruser21/CashCar/flaskenv/lib/python3.6/site-packages/flask_mail.py", line 165, in configure_host
    host.login(self.mail.username, self.mail.password)
  File "/usr/lib64/python3.6/smtplib.py", line 730, in login
    raise last_exception
  File "/usr/lib64/python3.6/smtplib.py", line 721, in login
    initial_response_ok=initial_response_ok)
  File "/usr/lib64/python3.6/smtplib.py", line 642, in auth
    raise SMTPAuthenticationError(code, resp)
smtplib.SMTPAuthenticationError: (534, b'5.7.14 <https://accounts.google.com/signin/continue?sarp=1&scc=1&plt=AKgnsbv\n5.7.14 jt4bxioaDXXQ33goFfK5pEEMREQGlqJWil2RBOILvWYp0JGylHyfNcreEIoEmLVhNvQ5C\n5.7.14 CMKeJf7HirMhf9S4C9A45-1evl15ZNdAtKJAfmqAjr_pdir0eY0PVxLfhhFpVB_7>\n5.7.14 Please log in via your web browser and then try again.\n5.7.14  Learn more at\n5.7.14  https://support.google.com/mail/answer/78754 c13sm1398732pjv.21 - gsmtp')
Exception on /user/information/point [GET]
Traceback (most recent call last):
  File "/Users/park/miniconda3/envs/basicFlask/lib/python3.8/site-packages/flask/app.py", line 2447, in wsgi_app
    response = self.full_dispatch_request()
  File "/Users/park/miniconda3/envs/basicFlask/lib/python3.8/site-packages/flask/app.py", line 1952, in full_dispatch_request
    rv = self.handle_user_exception(e)
  File "/Users/park/miniconda3/envs/basicFlask/lib/python3.8/site-packages/flask_cors/extension.py", line 165, in wrapped_function
    return cors_after_request(app.make_response(f(*args, **kwargs)))
  File "/Users/park/miniconda3/envs/basicFlask/lib/python3.8/site-packages/flask/app.py", line 1821, in handle_user_exception
    reraise(exc_type, exc_value, tb)
  File "/Users/park/miniconda3/envs/basicFlask/lib/python3.8/site-packages/flask/_compat.py", line 39, in reraise
    raise value
  File "/Users/park/miniconda3/envs/basicFlask/lib/python3.8/site-packages/flask/app.py", line 1950, in full_dispatch_request
    rv = self.dispatch_request()
  File "/Users/park/miniconda3/envs/basicFlask/lib/python3.8/site-packages/flask/app.py", line 1936, in dispatch_request
    return self.view_functions[rule.endpoint](**req.view_args)
  File "/Users/park/miniconda3/envs/basicFlask/lib/python3.8/site-packages/flask_jwt_extended/view_decorators.py", line 116, in decorator
    return fn(*args, **kwargs)
  File "/Users/park/miniconda3/envs/basicFlask/lib/python3.8/site-packages/flasgger/utils.py", line 273, in wrapper
    return function(*args, **kwargs)
  File "/Users/park/SolutionProjects/basicFlask/appConfig/routes.py", line 698, in user_point_information
    result = User.get_user_point_and_history(user_id=user_id)
  File "/Users/park/SolutionProjects/basicFlask/appConfig/models/user_model.py", line 505, in get_user_point_and_history
    user_scheduled_point += scheduled_point['additional_point']
KeyError: 'additional_point'
Exception on /user/information/point [GET]
Traceback (most recent call last):
  File "/Users/park/miniconda3/envs/basicFlask/lib/python3.8/site-packages/flask/app.py", line 2447, in wsgi_app
    response = self.full_dispatch_request()
  File "/Users/park/miniconda3/envs/basicFlask/lib/python3.8/site-packages/flask/app.py", line 1952, in full_dispatch_request
    rv = self.handle_user_exception(e)
  File "/Users/park/miniconda3/envs/basicFlask/lib/python3.8/site-packages/flask_cors/extension.py", line 165, in wrapped_function
    return cors_after_request(app.make_response(f(*args, **kwargs)))
  File "/Users/park/miniconda3/envs/basicFlask/lib/python3.8/site-packages/flask/app.py", line 1821, in handle_user_exception
    reraise(exc_type, exc_value, tb)
  File "/Users/park/miniconda3/envs/basicFlask/lib/python3.8/site-packages/flask/_compat.py", line 39, in reraise
    raise value
  File "/Users/park/miniconda3/envs/basicFlask/lib/python3.8/site-packages/flask/app.py", line 1950, in full_dispatch_request
    rv = self.dispatch_request()
  File "/Users/park/miniconda3/envs/basicFlask/lib/python3.8/site-packages/flask/app.py", line 1936, in dispatch_request
    return self.view_functions[rule.endpoint](**req.view_args)
  File "/Users/park/miniconda3/envs/basicFlask/lib/python3.8/site-packages/flask_jwt_extended/view_decorators.py", line 116, in decorator
    return fn(*args, **kwargs)
  File "/Users/park/miniconda3/envs/basicFlask/lib/python3.8/site-packages/flasgger/utils.py", line 273, in wrapper
    return function(*args, **kwargs)
  File "/Users/park/SolutionProjects/basicFlask/appConfig/routes.py", line 699, in user_point_information
    return jsonify({"data": result})
  File "/Users/park/miniconda3/envs/basicFlask/lib/python3.8/site-packages/flask/json/__init__.py", line 370, in jsonify
    dumps(data, indent=indent, separators=separators) + "\n",
  File "/Users/park/miniconda3/envs/basicFlask/lib/python3.8/site-packages/flask/json/__init__.py", line 211, in dumps
    rv = _json.dumps(obj, **kwargs)
  File "/Users/park/miniconda3/envs/basicFlask/lib/python3.8/json/__init__.py", line 234, in dumps
    return cls(
  File "/Users/park/miniconda3/envs/basicFlask/lib/python3.8/json/encoder.py", line 199, in encode
    chunks = self.iterencode(o, _one_shot=True)
  File "/Users/park/miniconda3/envs/basicFlask/lib/python3.8/json/encoder.py", line 257, in iterencode
    return _iterencode(o, 0)
  File "/Users/park/miniconda3/envs/basicFlask/lib/python3.8/site-packages/flasgger/base.py", line 792, in default
    return super(LazyJSONEncoder, self).default(obj)
  File "/Users/park/miniconda3/envs/basicFlask/lib/python3.8/site-packages/flask/json/__init__.py", line 100, in default
    return _json.JSONEncoder.default(self, o)
  File "/Users/park/miniconda3/envs/basicFlask/lib/python3.8/json/encoder.py", line 179, in default
    raise TypeError(f'Object of type {o.__class__.__name__} '
TypeError: Object of type Decimal is not JSON serializable
Exception on /user/information/point [GET]
Traceback (most recent call last):
  File "/Users/park/miniconda3/envs/basicFlask/lib/python3.8/site-packages/flask/app.py", line 2447, in wsgi_app
    response = self.full_dispatch_request()
  File "/Users/park/miniconda3/envs/basicFlask/lib/python3.8/site-packages/flask/app.py", line 1952, in full_dispatch_request
    rv = self.handle_user_exception(e)
  File "/Users/park/miniconda3/envs/basicFlask/lib/python3.8/site-packages/flask_cors/extension.py", line 165, in wrapped_function
    return cors_after_request(app.make_response(f(*args, **kwargs)))
  File "/Users/park/miniconda3/envs/basicFlask/lib/python3.8/site-packages/flask/app.py", line 1821, in handle_user_exception
    reraise(exc_type, exc_value, tb)
  File "/Users/park/miniconda3/envs/basicFlask/lib/python3.8/site-packages/flask/_compat.py", line 39, in reraise
    raise value
  File "/Users/park/miniconda3/envs/basicFlask/lib/python3.8/site-packages/flask/app.py", line 1950, in full_dispatch_request
    rv = self.dispatch_request()
  File "/Users/park/miniconda3/envs/basicFlask/lib/python3.8/site-packages/flask/app.py", line 1936, in dispatch_request
    return self.view_functions[rule.endpoint](**req.view_args)
  File "/Users/park/miniconda3/envs/basicFlask/lib/python3.8/site-packages/flask_jwt_extended/view_decorators.py", line 116, in decorator
    return fn(*args, **kwargs)
  File "/Users/park/miniconda3/envs/basicFlask/lib/python3.8/site-packages/flasgger/utils.py", line 273, in wrapper
    return function(*args, **kwargs)
  File "/Users/park/SolutionProjects/basicFlask/appConfig/routes.py", line 699, in user_point_information
    return jsonify({"data": result})
  File "/Users/park/miniconda3/envs/basicFlask/lib/python3.8/site-packages/flask/json/__init__.py", line 370, in jsonify
    dumps(data, indent=indent, separators=separators) + "\n",
  File "/Users/park/miniconda3/envs/basicFlask/lib/python3.8/site-packages/flask/json/__init__.py", line 211, in dumps
    rv = _json.dumps(obj, **kwargs)
  File "/Users/park/miniconda3/envs/basicFlask/lib/python3.8/json/__init__.py", line 234, in dumps
    return cls(
  File "/Users/park/miniconda3/envs/basicFlask/lib/python3.8/json/encoder.py", line 199, in encode
    chunks = self.iterencode(o, _one_shot=True)
  File "/Users/park/miniconda3/envs/basicFlask/lib/python3.8/json/encoder.py", line 257, in iterencode
    return _iterencode(o, 0)
  File "/Users/park/miniconda3/envs/basicFlask/lib/python3.8/site-packages/flasgger/base.py", line 792, in default
    return super(LazyJSONEncoder, self).default(obj)
  File "/Users/park/miniconda3/envs/basicFlask/lib/python3.8/site-packages/flask/json/__init__.py", line 100, in default
    return _json.JSONEncoder.default(self, o)
  File "/Users/park/miniconda3/envs/basicFlask/lib/python3.8/json/encoder.py", line 179, in default
    raise TypeError(f'Object of type {o.__class__.__name__} '
TypeError: Object of type Decimal is not JSON serializable
Exception on /app/version [GET]
Traceback (most recent call last):
  File "/Users/park/miniconda3/envs/basicFlask/lib/python3.8/site-packages/flask/app.py", line 2447, in wsgi_app
    response = self.full_dispatch_request()
  File "/Users/park/miniconda3/envs/basicFlask/lib/python3.8/site-packages/flask/app.py", line 1952, in full_dispatch_request
    rv = self.handle_user_exception(e)
  File "/Users/park/miniconda3/envs/basicFlask/lib/python3.8/site-packages/flask_cors/extension.py", line 165, in wrapped_function
    return cors_after_request(app.make_response(f(*args, **kwargs)))
  File "/Users/park/miniconda3/envs/basicFlask/lib/python3.8/site-packages/flask/app.py", line 1821, in handle_user_exception
    reraise(exc_type, exc_value, tb)
  File "/Users/park/miniconda3/envs/basicFlask/lib/python3.8/site-packages/flask/_compat.py", line 39, in reraise
    raise value
  File "/Users/park/miniconda3/envs/basicFlask/lib/python3.8/site-packages/flask/app.py", line 1950, in full_dispatch_request
    rv = self.dispatch_request()
  File "/Users/park/miniconda3/envs/basicFlask/lib/python3.8/site-packages/flask/app.py", line 1936, in dispatch_request
    return self.view_functions[rule.endpoint](**req.view_args)
  File "/Users/park/SolutionProjects/basicFlask/appConfig/routes.py", line 172, in app_version_check
    result = System.get_app_version_check(device=device)
  File "/Users/park/SolutionProjects/basicFlask/appConfig/models/system_model.py", line 17, in get_app_version_check
    result["version"] = int(app_version['version'])
TypeError: 'NoneType' object is not subscriptable
<<<<<<< HEAD
Exception on /user/new-password [POST]
Traceback (most recent call last):
  File "/home/cashcaruser21/CashCar/flaskenv/lib/python3.6/site-packages/flask/app.py", line 2447, in wsgi_app
    response = self.full_dispatch_request()
  File "/home/cashcaruser21/CashCar/flaskenv/lib/python3.6/site-packages/flask/app.py", line 1952, in full_dispatch_request
    rv = self.handle_user_exception(e)
  File "/home/cashcaruser21/CashCar/flaskenv/lib/python3.6/site-packages/flask_cors/extension.py", line 165, in wrapped_function
    return cors_after_request(app.make_response(f(*args, **kwargs)))
  File "/home/cashcaruser21/CashCar/flaskenv/lib/python3.6/site-packages/flask/app.py", line 1821, in handle_user_exception
    reraise(exc_type, exc_value, tb)
  File "/home/cashcaruser21/CashCar/flaskenv/lib/python3.6/site-packages/flask/_compat.py", line 39, in reraise
    raise value
  File "/home/cashcaruser21/CashCar/flaskenv/lib/python3.6/site-packages/flask/app.py", line 1950, in full_dispatch_request
    rv = self.dispatch_request()
  File "/home/cashcaruser21/CashCar/flaskenv/lib/python3.6/site-packages/flask/app.py", line 1936, in dispatch_request
    return self.view_functions[rule.endpoint](**req.view_args)
  File "/home/cashcaruser21/CashCar/flaskenv/lib/python3.6/site-packages/flask_jwt_extended/view_decorators.py", line 116, in decorator
    return fn(*args, **kwargs)
  File "/home/cashcaruser21/CashCar/flaskenv/lib/python3.6/site-packages/flasgger/utils.py", line 273, in wrapper
    return function(*args, **kwargs)
  File "./routes.py", line 241, in user_new_password
    result = User.login_user_change_password(user_id=user_id, **data)
  File "./models/user_model.py", line 580, in login_user_change_password
    if kwargs['login_type'] == "normal":
KeyError: 'login_type'
Exception on /user/new-password [POST]
Traceback (most recent call last):
  File "/home/cashcaruser21/CashCar/flaskenv/lib/python3.6/site-packages/flask/app.py", line 2447, in wsgi_app
    response = self.full_dispatch_request()
  File "/home/cashcaruser21/CashCar/flaskenv/lib/python3.6/site-packages/flask/app.py", line 1952, in full_dispatch_request
    rv = self.handle_user_exception(e)
  File "/home/cashcaruser21/CashCar/flaskenv/lib/python3.6/site-packages/flask_cors/extension.py", line 165, in wrapped_function
    return cors_after_request(app.make_response(f(*args, **kwargs)))
  File "/home/cashcaruser21/CashCar/flaskenv/lib/python3.6/site-packages/flask/app.py", line 1821, in handle_user_exception
    reraise(exc_type, exc_value, tb)
  File "/home/cashcaruser21/CashCar/flaskenv/lib/python3.6/site-packages/flask/_compat.py", line 39, in reraise
    raise value
  File "/home/cashcaruser21/CashCar/flaskenv/lib/python3.6/site-packages/flask/app.py", line 1950, in full_dispatch_request
    rv = self.dispatch_request()
  File "/home/cashcaruser21/CashCar/flaskenv/lib/python3.6/site-packages/flask/app.py", line 1936, in dispatch_request
    return self.view_functions[rule.endpoint](**req.view_args)
  File "/home/cashcaruser21/CashCar/flaskenv/lib/python3.6/site-packages/flask_jwt_extended/view_decorators.py", line 116, in decorator
    return fn(*args, **kwargs)
  File "/home/cashcaruser21/CashCar/flaskenv/lib/python3.6/site-packages/flasgger/utils.py", line 273, in wrapper
    return function(*args, **kwargs)
  File "./routes.py", line 241, in user_new_password
    result = User.login_user_change_password(user_id=user_id, **data)
  File "./models/user_model.py", line 580, in login_user_change_password
    if kwargs['login_type'] == "normal":
KeyError: 'login_type'
Exception on /user/new-password [POST]
Traceback (most recent call last):
  File "/home/cashcaruser21/CashCar/flaskenv/lib/python3.6/site-packages/flask/app.py", line 2447, in wsgi_app
    response = self.full_dispatch_request()
  File "/home/cashcaruser21/CashCar/flaskenv/lib/python3.6/site-packages/flask/app.py", line 1952, in full_dispatch_request
    rv = self.handle_user_exception(e)
  File "/home/cashcaruser21/CashCar/flaskenv/lib/python3.6/site-packages/flask_cors/extension.py", line 165, in wrapped_function
    return cors_after_request(app.make_response(f(*args, **kwargs)))
  File "/home/cashcaruser21/CashCar/flaskenv/lib/python3.6/site-packages/flask/app.py", line 1821, in handle_user_exception
    reraise(exc_type, exc_value, tb)
  File "/home/cashcaruser21/CashCar/flaskenv/lib/python3.6/site-packages/flask/_compat.py", line 39, in reraise
    raise value
  File "/home/cashcaruser21/CashCar/flaskenv/lib/python3.6/site-packages/flask/app.py", line 1950, in full_dispatch_request
    rv = self.dispatch_request()
  File "/home/cashcaruser21/CashCar/flaskenv/lib/python3.6/site-packages/flask/app.py", line 1936, in dispatch_request
    return self.view_functions[rule.endpoint](**req.view_args)
  File "/home/cashcaruser21/CashCar/flaskenv/lib/python3.6/site-packages/flask_jwt_extended/view_decorators.py", line 116, in decorator
    return fn(*args, **kwargs)
  File "/home/cashcaruser21/CashCar/flaskenv/lib/python3.6/site-packages/flasgger/utils.py", line 273, in wrapper
    return function(*args, **kwargs)
  File "./routes.py", line 241, in user_new_password
    result = User.login_user_change_password(user_id=user_id, **data)
  File "./models/user_model.py", line 580, in login_user_change_password
    if kwargs['login_type'] == "normal":
KeyError: 'login_type'
Exception on /user/new-password [POST]
Traceback (most recent call last):
  File "/home/cashcaruser21/CashCar/flaskenv/lib/python3.6/site-packages/flask/app.py", line 2447, in wsgi_app
    response = self.full_dispatch_request()
  File "/home/cashcaruser21/CashCar/flaskenv/lib/python3.6/site-packages/flask/app.py", line 1952, in full_dispatch_request
    rv = self.handle_user_exception(e)
  File "/home/cashcaruser21/CashCar/flaskenv/lib/python3.6/site-packages/flask_cors/extension.py", line 165, in wrapped_function
    return cors_after_request(app.make_response(f(*args, **kwargs)))
  File "/home/cashcaruser21/CashCar/flaskenv/lib/python3.6/site-packages/flask/app.py", line 1821, in handle_user_exception
    reraise(exc_type, exc_value, tb)
  File "/home/cashcaruser21/CashCar/flaskenv/lib/python3.6/site-packages/flask/_compat.py", line 39, in reraise
    raise value
  File "/home/cashcaruser21/CashCar/flaskenv/lib/python3.6/site-packages/flask/app.py", line 1950, in full_dispatch_request
    rv = self.dispatch_request()
  File "/home/cashcaruser21/CashCar/flaskenv/lib/python3.6/site-packages/flask/app.py", line 1936, in dispatch_request
    return self.view_functions[rule.endpoint](**req.view_args)
  File "/home/cashcaruser21/CashCar/flaskenv/lib/python3.6/site-packages/flask_jwt_extended/view_decorators.py", line 116, in decorator
    return fn(*args, **kwargs)
  File "/home/cashcaruser21/CashCar/flaskenv/lib/python3.6/site-packages/flasgger/utils.py", line 273, in wrapper
    return function(*args, **kwargs)
  File "./routes.py", line 241, in user_new_password
    result = User.login_user_change_password(user_id=user_id, **data)
  File "./models/user_model.py", line 580, in login_user_change_password
    if kwargs['login_type'] == "normal":
KeyError: 'login_type'
Exception on /oauth/kakao/callback [GET]
Traceback (most recent call last):
  File "/Users/park/SolutionProjects/basicFlask/appConfig/routes.py", line 218, in kakao_callback
    token_json = token_request.json()
  File "/Users/park/miniconda3/envs/basicFlask/lib/python3.8/site-packages/requests/models.py", line 900, in json
    return complexjson.loads(self.text, **kwargs)
  File "/Users/park/miniconda3/envs/basicFlask/lib/python3.8/json/__init__.py", line 357, in loads
    return _default_decoder.decode(s)
  File "/Users/park/miniconda3/envs/basicFlask/lib/python3.8/json/decoder.py", line 337, in decode
    obj, end = self.raw_decode(s, idx=_w(s, 0).end())
  File "/Users/park/miniconda3/envs/basicFlask/lib/python3.8/json/decoder.py", line 355, in raw_decode
    raise JSONDecodeError("Expecting value", s, err.value) from None
json.decoder.JSONDecodeError: Expecting value: line 2 column 1 (char 1)

During handling of the above exception, another exception occurred:

Traceback (most recent call last):
  File "/Users/park/miniconda3/envs/basicFlask/lib/python3.8/site-packages/flask/app.py", line 2447, in wsgi_app
    response = self.full_dispatch_request()
  File "/Users/park/miniconda3/envs/basicFlask/lib/python3.8/site-packages/flask/app.py", line 1952, in full_dispatch_request
    rv = self.handle_user_exception(e)
  File "/Users/park/miniconda3/envs/basicFlask/lib/python3.8/site-packages/flask_cors/extension.py", line 165, in wrapped_function
    return cors_after_request(app.make_response(f(*args, **kwargs)))
  File "/Users/park/miniconda3/envs/basicFlask/lib/python3.8/site-packages/flask/app.py", line 1821, in handle_user_exception
    reraise(exc_type, exc_value, tb)
  File "/Users/park/miniconda3/envs/basicFlask/lib/python3.8/site-packages/flask/_compat.py", line 39, in reraise
    raise value
  File "/Users/park/miniconda3/envs/basicFlask/lib/python3.8/site-packages/flask/app.py", line 1950, in full_dispatch_request
    rv = self.dispatch_request()
  File "/Users/park/miniconda3/envs/basicFlask/lib/python3.8/site-packages/flask/app.py", line 1936, in dispatch_request
    return self.view_functions[rule.endpoint](**req.view_args)
  File "/Users/park/SolutionProjects/basicFlask/appConfig/routes.py", line 233, in kakao_callback
    except access_token.DoesNotExist:
UnboundLocalError: local variable 'access_token' referenced before assignment
Exception on /oauth/kakao/callback [GET]
Traceback (most recent call last):
  File "/Users/park/miniconda3/envs/basicFlask/lib/python3.8/site-packages/flask/app.py", line 2447, in wsgi_app
    response = self.full_dispatch_request()
  File "/Users/park/miniconda3/envs/basicFlask/lib/python3.8/site-packages/flask/app.py", line 1952, in full_dispatch_request
    rv = self.handle_user_exception(e)
  File "/Users/park/miniconda3/envs/basicFlask/lib/python3.8/site-packages/flask_cors/extension.py", line 165, in wrapped_function
    return cors_after_request(app.make_response(f(*args, **kwargs)))
  File "/Users/park/miniconda3/envs/basicFlask/lib/python3.8/site-packages/flask/app.py", line 1821, in handle_user_exception
    reraise(exc_type, exc_value, tb)
  File "/Users/park/miniconda3/envs/basicFlask/lib/python3.8/site-packages/flask/_compat.py", line 39, in reraise
    raise value
  File "/Users/park/miniconda3/envs/basicFlask/lib/python3.8/site-packages/flask/app.py", line 1950, in full_dispatch_request
    rv = self.dispatch_request()
  File "/Users/park/miniconda3/envs/basicFlask/lib/python3.8/site-packages/flask/app.py", line 1936, in dispatch_request
    return self.view_functions[rule.endpoint](**req.view_args)
  File "/Users/park/SolutionProjects/basicFlask/appConfig/routes.py", line 218, in kakao_callback
    token_json = token_request.json()
  File "/Users/park/miniconda3/envs/basicFlask/lib/python3.8/site-packages/requests/models.py", line 900, in json
    return complexjson.loads(self.text, **kwargs)
  File "/Users/park/miniconda3/envs/basicFlask/lib/python3.8/json/__init__.py", line 357, in loads
    return _default_decoder.decode(s)
  File "/Users/park/miniconda3/envs/basicFlask/lib/python3.8/json/decoder.py", line 337, in decode
    obj, end = self.raw_decode(s, idx=_w(s, 0).end())
  File "/Users/park/miniconda3/envs/basicFlask/lib/python3.8/json/decoder.py", line 355, in raw_decode
    raise JSONDecodeError("Expecting value", s, err.value) from None
json.decoder.JSONDecodeError: Expecting value: line 2 column 1 (char 1)
Exception on /oauth/kakao/callback [GET]
Traceback (most recent call last):
  File "/Users/park/miniconda3/envs/basicFlask/lib/python3.8/site-packages/flask/app.py", line 2447, in wsgi_app
    response = self.full_dispatch_request()
  File "/Users/park/miniconda3/envs/basicFlask/lib/python3.8/site-packages/flask/app.py", line 1952, in full_dispatch_request
    rv = self.handle_user_exception(e)
  File "/Users/park/miniconda3/envs/basicFlask/lib/python3.8/site-packages/flask_cors/extension.py", line 165, in wrapped_function
    return cors_after_request(app.make_response(f(*args, **kwargs)))
  File "/Users/park/miniconda3/envs/basicFlask/lib/python3.8/site-packages/flask/app.py", line 1821, in handle_user_exception
    reraise(exc_type, exc_value, tb)
  File "/Users/park/miniconda3/envs/basicFlask/lib/python3.8/site-packages/flask/_compat.py", line 39, in reraise
    raise value
  File "/Users/park/miniconda3/envs/basicFlask/lib/python3.8/site-packages/flask/app.py", line 1950, in full_dispatch_request
    rv = self.dispatch_request()
  File "/Users/park/miniconda3/envs/basicFlask/lib/python3.8/site-packages/flask/app.py", line 1936, in dispatch_request
    return self.view_functions[rule.endpoint](**req.view_args)
  File "/Users/park/SolutionProjects/basicFlask/appConfig/routes.py", line 219, in kakao_callback
    token_json = token_request.json()
  File "/Users/park/miniconda3/envs/basicFlask/lib/python3.8/site-packages/requests/models.py", line 900, in json
    return complexjson.loads(self.text, **kwargs)
  File "/Users/park/miniconda3/envs/basicFlask/lib/python3.8/json/__init__.py", line 357, in loads
    return _default_decoder.decode(s)
  File "/Users/park/miniconda3/envs/basicFlask/lib/python3.8/json/decoder.py", line 337, in decode
    obj, end = self.raw_decode(s, idx=_w(s, 0).end())
  File "/Users/park/miniconda3/envs/basicFlask/lib/python3.8/json/decoder.py", line 355, in raw_decode
    raise JSONDecodeError("Expecting value", s, err.value) from None
json.decoder.JSONDecodeError: Expecting value: line 2 column 1 (char 1)
Exception on /oauth/kakao/callback [GET]
Traceback (most recent call last):
  File "/Users/park/miniconda3/envs/basicFlask/lib/python3.8/site-packages/flask/app.py", line 2447, in wsgi_app
    response = self.full_dispatch_request()
  File "/Users/park/miniconda3/envs/basicFlask/lib/python3.8/site-packages/flask/app.py", line 1952, in full_dispatch_request
    rv = self.handle_user_exception(e)
  File "/Users/park/miniconda3/envs/basicFlask/lib/python3.8/site-packages/flask_cors/extension.py", line 165, in wrapped_function
    return cors_after_request(app.make_response(f(*args, **kwargs)))
  File "/Users/park/miniconda3/envs/basicFlask/lib/python3.8/site-packages/flask/app.py", line 1821, in handle_user_exception
    reraise(exc_type, exc_value, tb)
  File "/Users/park/miniconda3/envs/basicFlask/lib/python3.8/site-packages/flask/_compat.py", line 39, in reraise
    raise value
  File "/Users/park/miniconda3/envs/basicFlask/lib/python3.8/site-packages/flask/app.py", line 1950, in full_dispatch_request
    rv = self.dispatch_request()
  File "/Users/park/miniconda3/envs/basicFlask/lib/python3.8/site-packages/flask/app.py", line 1936, in dispatch_request
    return self.view_functions[rule.endpoint](**req.view_args)
  File "/Users/park/SolutionProjects/basicFlask/appConfig/routes.py", line 219, in kakao_callback
    token_json = token_request.json().decode('utf-8')
  File "/Users/park/miniconda3/envs/basicFlask/lib/python3.8/site-packages/requests/models.py", line 900, in json
    return complexjson.loads(self.text, **kwargs)
  File "/Users/park/miniconda3/envs/basicFlask/lib/python3.8/json/__init__.py", line 357, in loads
    return _default_decoder.decode(s)
  File "/Users/park/miniconda3/envs/basicFlask/lib/python3.8/json/decoder.py", line 337, in decode
    obj, end = self.raw_decode(s, idx=_w(s, 0).end())
  File "/Users/park/miniconda3/envs/basicFlask/lib/python3.8/json/decoder.py", line 355, in raw_decode
    raise JSONDecodeError("Expecting value", s, err.value) from None
json.decoder.JSONDecodeError: Expecting value: line 2 column 1 (char 1)
Exception on /oauth/kakao/callback [GET]
Traceback (most recent call last):
  File "/Users/park/miniconda3/envs/basicFlask/lib/python3.8/site-packages/flask/app.py", line 2447, in wsgi_app
    response = self.full_dispatch_request()
  File "/Users/park/miniconda3/envs/basicFlask/lib/python3.8/site-packages/flask/app.py", line 1952, in full_dispatch_request
    rv = self.handle_user_exception(e)
  File "/Users/park/miniconda3/envs/basicFlask/lib/python3.8/site-packages/flask_cors/extension.py", line 165, in wrapped_function
    return cors_after_request(app.make_response(f(*args, **kwargs)))
  File "/Users/park/miniconda3/envs/basicFlask/lib/python3.8/site-packages/flask/app.py", line 1821, in handle_user_exception
    reraise(exc_type, exc_value, tb)
  File "/Users/park/miniconda3/envs/basicFlask/lib/python3.8/site-packages/flask/_compat.py", line 39, in reraise
    raise value
  File "/Users/park/miniconda3/envs/basicFlask/lib/python3.8/site-packages/flask/app.py", line 1950, in full_dispatch_request
    rv = self.dispatch_request()
  File "/Users/park/miniconda3/envs/basicFlask/lib/python3.8/site-packages/flask/app.py", line 1936, in dispatch_request
    return self.view_functions[rule.endpoint](**req.view_args)
  File "/Users/park/SolutionProjects/basicFlask/appConfig/routes.py", line 218, in kakao_callback
    token_json = token_request.json().decode('utf-8')
  File "/Users/park/miniconda3/envs/basicFlask/lib/python3.8/site-packages/requests/models.py", line 900, in json
    return complexjson.loads(self.text, **kwargs)
  File "/Users/park/miniconda3/envs/basicFlask/lib/python3.8/json/__init__.py", line 357, in loads
    return _default_decoder.decode(s)
  File "/Users/park/miniconda3/envs/basicFlask/lib/python3.8/json/decoder.py", line 337, in decode
    obj, end = self.raw_decode(s, idx=_w(s, 0).end())
  File "/Users/park/miniconda3/envs/basicFlask/lib/python3.8/json/decoder.py", line 355, in raw_decode
    raise JSONDecodeError("Expecting value", s, err.value) from None
json.decoder.JSONDecodeError: Expecting value: line 2 column 1 (char 1)
Exception on /oauth/kakao/callback [GET]
Traceback (most recent call last):
  File "/Users/park/miniconda3/envs/basicFlask/lib/python3.8/site-packages/flask/app.py", line 2447, in wsgi_app
    response = self.full_dispatch_request()
  File "/Users/park/miniconda3/envs/basicFlask/lib/python3.8/site-packages/flask/app.py", line 1952, in full_dispatch_request
    rv = self.handle_user_exception(e)
  File "/Users/park/miniconda3/envs/basicFlask/lib/python3.8/site-packages/flask_cors/extension.py", line 165, in wrapped_function
    return cors_after_request(app.make_response(f(*args, **kwargs)))
  File "/Users/park/miniconda3/envs/basicFlask/lib/python3.8/site-packages/flask/app.py", line 1821, in handle_user_exception
    reraise(exc_type, exc_value, tb)
  File "/Users/park/miniconda3/envs/basicFlask/lib/python3.8/site-packages/flask/_compat.py", line 39, in reraise
    raise value
  File "/Users/park/miniconda3/envs/basicFlask/lib/python3.8/site-packages/flask/app.py", line 1950, in full_dispatch_request
    rv = self.dispatch_request()
  File "/Users/park/miniconda3/envs/basicFlask/lib/python3.8/site-packages/flask/app.py", line 1936, in dispatch_request
    return self.view_functions[rule.endpoint](**req.view_args)
  File "/Users/park/SolutionProjects/basicFlask/appConfig/routes.py", line 218, in kakao_callback
    token_json = token_request.json().decode('utf-8')
  File "/Users/park/miniconda3/envs/basicFlask/lib/python3.8/site-packages/requests/models.py", line 900, in json
    return complexjson.loads(self.text, **kwargs)
  File "/Users/park/miniconda3/envs/basicFlask/lib/python3.8/json/__init__.py", line 357, in loads
    return _default_decoder.decode(s)
  File "/Users/park/miniconda3/envs/basicFlask/lib/python3.8/json/decoder.py", line 337, in decode
    obj, end = self.raw_decode(s, idx=_w(s, 0).end())
  File "/Users/park/miniconda3/envs/basicFlask/lib/python3.8/json/decoder.py", line 355, in raw_decode
    raise JSONDecodeError("Expecting value", s, err.value) from None
json.decoder.JSONDecodeError: Expecting value: line 2 column 1 (char 1)
Exception on /oauth/kakao/callback [GET]
Traceback (most recent call last):
  File "/Users/park/miniconda3/envs/basicFlask/lib/python3.8/site-packages/flask/app.py", line 2447, in wsgi_app
    response = self.full_dispatch_request()
  File "/Users/park/miniconda3/envs/basicFlask/lib/python3.8/site-packages/flask/app.py", line 1952, in full_dispatch_request
    rv = self.handle_user_exception(e)
  File "/Users/park/miniconda3/envs/basicFlask/lib/python3.8/site-packages/flask_cors/extension.py", line 165, in wrapped_function
    return cors_after_request(app.make_response(f(*args, **kwargs)))
  File "/Users/park/miniconda3/envs/basicFlask/lib/python3.8/site-packages/flask/app.py", line 1821, in handle_user_exception
    reraise(exc_type, exc_value, tb)
  File "/Users/park/miniconda3/envs/basicFlask/lib/python3.8/site-packages/flask/_compat.py", line 39, in reraise
    raise value
  File "/Users/park/miniconda3/envs/basicFlask/lib/python3.8/site-packages/flask/app.py", line 1950, in full_dispatch_request
    rv = self.dispatch_request()
  File "/Users/park/miniconda3/envs/basicFlask/lib/python3.8/site-packages/flask/app.py", line 1936, in dispatch_request
    return self.view_functions[rule.endpoint](**req.view_args)
  File "/Users/park/SolutionProjects/basicFlask/appConfig/routes.py", line 218, in kakao_callback
    token_json = token_request.json().decode('utf-8')
  File "/Users/park/miniconda3/envs/basicFlask/lib/python3.8/site-packages/requests/models.py", line 900, in json
    return complexjson.loads(self.text, **kwargs)
  File "/Users/park/miniconda3/envs/basicFlask/lib/python3.8/json/__init__.py", line 357, in loads
    return _default_decoder.decode(s)
  File "/Users/park/miniconda3/envs/basicFlask/lib/python3.8/json/decoder.py", line 337, in decode
    obj, end = self.raw_decode(s, idx=_w(s, 0).end())
  File "/Users/park/miniconda3/envs/basicFlask/lib/python3.8/json/decoder.py", line 355, in raw_decode
    raise JSONDecodeError("Expecting value", s, err.value) from None
json.decoder.JSONDecodeError: Expecting value: line 2 column 1 (char 1)
Exception on /oauth/kakao/callback [GET]
Traceback (most recent call last):
  File "/Users/park/miniconda3/envs/basicFlask/lib/python3.8/site-packages/flask/app.py", line 2447, in wsgi_app
    response = self.full_dispatch_request()
  File "/Users/park/miniconda3/envs/basicFlask/lib/python3.8/site-packages/flask/app.py", line 1952, in full_dispatch_request
    rv = self.handle_user_exception(e)
  File "/Users/park/miniconda3/envs/basicFlask/lib/python3.8/site-packages/flask_cors/extension.py", line 165, in wrapped_function
    return cors_after_request(app.make_response(f(*args, **kwargs)))
  File "/Users/park/miniconda3/envs/basicFlask/lib/python3.8/site-packages/flask/app.py", line 1821, in handle_user_exception
    reraise(exc_type, exc_value, tb)
  File "/Users/park/miniconda3/envs/basicFlask/lib/python3.8/site-packages/flask/_compat.py", line 39, in reraise
    raise value
  File "/Users/park/miniconda3/envs/basicFlask/lib/python3.8/site-packages/flask/app.py", line 1950, in full_dispatch_request
    rv = self.dispatch_request()
  File "/Users/park/miniconda3/envs/basicFlask/lib/python3.8/site-packages/flask/app.py", line 1936, in dispatch_request
    return self.view_functions[rule.endpoint](**req.view_args)
  File "/Users/park/SolutionProjects/basicFlask/appConfig/routes.py", line 218, in kakao_callback
    token_json = token_request.json().decode('utf-8')
  File "/Users/park/miniconda3/envs/basicFlask/lib/python3.8/site-packages/requests/models.py", line 900, in json
    return complexjson.loads(self.text, **kwargs)
  File "/Users/park/miniconda3/envs/basicFlask/lib/python3.8/json/__init__.py", line 357, in loads
    return _default_decoder.decode(s)
  File "/Users/park/miniconda3/envs/basicFlask/lib/python3.8/json/decoder.py", line 337, in decode
    obj, end = self.raw_decode(s, idx=_w(s, 0).end())
  File "/Users/park/miniconda3/envs/basicFlask/lib/python3.8/json/decoder.py", line 355, in raw_decode
    raise JSONDecodeError("Expecting value", s, err.value) from None
json.decoder.JSONDecodeError: Expecting value: line 2 column 1 (char 1)
Exception on /oauth/kakao/callback [GET]
Traceback (most recent call last):
  File "/Users/park/miniconda3/envs/basicFlask/lib/python3.8/site-packages/flask/app.py", line 2447, in wsgi_app
    response = self.full_dispatch_request()
  File "/Users/park/miniconda3/envs/basicFlask/lib/python3.8/site-packages/flask/app.py", line 1952, in full_dispatch_request
    rv = self.handle_user_exception(e)
  File "/Users/park/miniconda3/envs/basicFlask/lib/python3.8/site-packages/flask_cors/extension.py", line 165, in wrapped_function
    return cors_after_request(app.make_response(f(*args, **kwargs)))
  File "/Users/park/miniconda3/envs/basicFlask/lib/python3.8/site-packages/flask/app.py", line 1821, in handle_user_exception
    reraise(exc_type, exc_value, tb)
  File "/Users/park/miniconda3/envs/basicFlask/lib/python3.8/site-packages/flask/_compat.py", line 39, in reraise
    raise value
  File "/Users/park/miniconda3/envs/basicFlask/lib/python3.8/site-packages/flask/app.py", line 1950, in full_dispatch_request
    rv = self.dispatch_request()
  File "/Users/park/miniconda3/envs/basicFlask/lib/python3.8/site-packages/flask/app.py", line 1936, in dispatch_request
    return self.view_functions[rule.endpoint](**req.view_args)
  File "/Users/park/SolutionProjects/basicFlask/appConfig/routes.py", line 218, in kakao_callback
    token_json = token_request.json().decode('utf-8')
  File "/Users/park/miniconda3/envs/basicFlask/lib/python3.8/site-packages/requests/models.py", line 900, in json
    return complexjson.loads(self.text, **kwargs)
  File "/Users/park/miniconda3/envs/basicFlask/lib/python3.8/json/__init__.py", line 357, in loads
    return _default_decoder.decode(s)
  File "/Users/park/miniconda3/envs/basicFlask/lib/python3.8/json/decoder.py", line 337, in decode
    obj, end = self.raw_decode(s, idx=_w(s, 0).end())
  File "/Users/park/miniconda3/envs/basicFlask/lib/python3.8/json/decoder.py", line 355, in raw_decode
    raise JSONDecodeError("Expecting value", s, err.value) from None
json.decoder.JSONDecodeError: Expecting value: line 2 column 1 (char 1)
Exception on /oauth/kakao/callback [GET]
Traceback (most recent call last):
  File "/Users/park/miniconda3/envs/basicFlask/lib/python3.8/site-packages/flask/app.py", line 2447, in wsgi_app
    response = self.full_dispatch_request()
  File "/Users/park/miniconda3/envs/basicFlask/lib/python3.8/site-packages/flask/app.py", line 1952, in full_dispatch_request
    rv = self.handle_user_exception(e)
  File "/Users/park/miniconda3/envs/basicFlask/lib/python3.8/site-packages/flask_cors/extension.py", line 165, in wrapped_function
    return cors_after_request(app.make_response(f(*args, **kwargs)))
  File "/Users/park/miniconda3/envs/basicFlask/lib/python3.8/site-packages/flask/app.py", line 1821, in handle_user_exception
    reraise(exc_type, exc_value, tb)
  File "/Users/park/miniconda3/envs/basicFlask/lib/python3.8/site-packages/flask/_compat.py", line 39, in reraise
    raise value
  File "/Users/park/miniconda3/envs/basicFlask/lib/python3.8/site-packages/flask/app.py", line 1950, in full_dispatch_request
    rv = self.dispatch_request()
  File "/Users/park/miniconda3/envs/basicFlask/lib/python3.8/site-packages/flask/app.py", line 1936, in dispatch_request
    return self.view_functions[rule.endpoint](**req.view_args)
  File "/Users/park/SolutionProjects/basicFlask/appConfig/routes.py", line 219, in kakao_callback
    token_json = token_request.json().decode('utf-8')
  File "/Users/park/miniconda3/envs/basicFlask/lib/python3.8/site-packages/requests/models.py", line 900, in json
    return complexjson.loads(self.text, **kwargs)
  File "/Users/park/miniconda3/envs/basicFlask/lib/python3.8/json/__init__.py", line 357, in loads
    return _default_decoder.decode(s)
  File "/Users/park/miniconda3/envs/basicFlask/lib/python3.8/json/decoder.py", line 337, in decode
    obj, end = self.raw_decode(s, idx=_w(s, 0).end())
  File "/Users/park/miniconda3/envs/basicFlask/lib/python3.8/json/decoder.py", line 355, in raw_decode
    raise JSONDecodeError("Expecting value", s, err.value) from None
json.decoder.JSONDecodeError: Expecting value: line 2 column 1 (char 1)
Exception on /oauth/kakao/callback [GET]
Traceback (most recent call last):
  File "/Users/park/miniconda3/envs/basicFlask/lib/python3.8/site-packages/flask/app.py", line 2447, in wsgi_app
    response = self.full_dispatch_request()
  File "/Users/park/miniconda3/envs/basicFlask/lib/python3.8/site-packages/flask/app.py", line 1952, in full_dispatch_request
    rv = self.handle_user_exception(e)
  File "/Users/park/miniconda3/envs/basicFlask/lib/python3.8/site-packages/flask_cors/extension.py", line 165, in wrapped_function
    return cors_after_request(app.make_response(f(*args, **kwargs)))
  File "/Users/park/miniconda3/envs/basicFlask/lib/python3.8/site-packages/flask/app.py", line 1821, in handle_user_exception
    reraise(exc_type, exc_value, tb)
  File "/Users/park/miniconda3/envs/basicFlask/lib/python3.8/site-packages/flask/_compat.py", line 39, in reraise
    raise value
  File "/Users/park/miniconda3/envs/basicFlask/lib/python3.8/site-packages/flask/app.py", line 1950, in full_dispatch_request
    rv = self.dispatch_request()
  File "/Users/park/miniconda3/envs/basicFlask/lib/python3.8/site-packages/flask/app.py", line 1936, in dispatch_request
    return self.view_functions[rule.endpoint](**req.view_args)
  File "/Users/park/SolutionProjects/basicFlask/appConfig/routes.py", line 219, in kakao_callback
    token_json = token_request.json().decode('utf-8')
  File "/Users/park/miniconda3/envs/basicFlask/lib/python3.8/site-packages/requests/models.py", line 900, in json
    return complexjson.loads(self.text, **kwargs)
  File "/Users/park/miniconda3/envs/basicFlask/lib/python3.8/json/__init__.py", line 357, in loads
    return _default_decoder.decode(s)
  File "/Users/park/miniconda3/envs/basicFlask/lib/python3.8/json/decoder.py", line 337, in decode
    obj, end = self.raw_decode(s, idx=_w(s, 0).end())
  File "/Users/park/miniconda3/envs/basicFlask/lib/python3.8/json/decoder.py", line 355, in raw_decode
    raise JSONDecodeError("Expecting value", s, err.value) from None
json.decoder.JSONDecodeError: Expecting value: line 2 column 1 (char 1)
Exception on /oauth/kakao/callback [GET]
Traceback (most recent call last):
  File "/Users/park/miniconda3/envs/basicFlask/lib/python3.8/site-packages/flask/app.py", line 2447, in wsgi_app
    response = self.full_dispatch_request()
  File "/Users/park/miniconda3/envs/basicFlask/lib/python3.8/site-packages/flask/app.py", line 1952, in full_dispatch_request
    rv = self.handle_user_exception(e)
  File "/Users/park/miniconda3/envs/basicFlask/lib/python3.8/site-packages/flask_cors/extension.py", line 165, in wrapped_function
    return cors_after_request(app.make_response(f(*args, **kwargs)))
  File "/Users/park/miniconda3/envs/basicFlask/lib/python3.8/site-packages/flask/app.py", line 1821, in handle_user_exception
    reraise(exc_type, exc_value, tb)
  File "/Users/park/miniconda3/envs/basicFlask/lib/python3.8/site-packages/flask/_compat.py", line 39, in reraise
    raise value
  File "/Users/park/miniconda3/envs/basicFlask/lib/python3.8/site-packages/flask/app.py", line 1950, in full_dispatch_request
    rv = self.dispatch_request()
  File "/Users/park/miniconda3/envs/basicFlask/lib/python3.8/site-packages/flask/app.py", line 1936, in dispatch_request
    return self.view_functions[rule.endpoint](**req.view_args)
  File "/Users/park/SolutionProjects/basicFlask/appConfig/routes.py", line 219, in kakao_callback
    token_json = token_request.json().decode('utf-8')
  File "/Users/park/miniconda3/envs/basicFlask/lib/python3.8/site-packages/requests/models.py", line 900, in json
    return complexjson.loads(self.text, **kwargs)
  File "/Users/park/miniconda3/envs/basicFlask/lib/python3.8/json/__init__.py", line 357, in loads
    return _default_decoder.decode(s)
  File "/Users/park/miniconda3/envs/basicFlask/lib/python3.8/json/decoder.py", line 337, in decode
    obj, end = self.raw_decode(s, idx=_w(s, 0).end())
  File "/Users/park/miniconda3/envs/basicFlask/lib/python3.8/json/decoder.py", line 355, in raw_decode
    raise JSONDecodeError("Expecting value", s, err.value) from None
json.decoder.JSONDecodeError: Expecting value: line 2 column 1 (char 1)
Exception on /oauth/kakao/callback [GET]
Traceback (most recent call last):
  File "/Users/park/miniconda3/envs/basicFlask/lib/python3.8/site-packages/flask/app.py", line 2447, in wsgi_app
    response = self.full_dispatch_request()
  File "/Users/park/miniconda3/envs/basicFlask/lib/python3.8/site-packages/flask/app.py", line 1952, in full_dispatch_request
    rv = self.handle_user_exception(e)
  File "/Users/park/miniconda3/envs/basicFlask/lib/python3.8/site-packages/flask_cors/extension.py", line 165, in wrapped_function
    return cors_after_request(app.make_response(f(*args, **kwargs)))
  File "/Users/park/miniconda3/envs/basicFlask/lib/python3.8/site-packages/flask/app.py", line 1821, in handle_user_exception
    reraise(exc_type, exc_value, tb)
  File "/Users/park/miniconda3/envs/basicFlask/lib/python3.8/site-packages/flask/_compat.py", line 39, in reraise
    raise value
  File "/Users/park/miniconda3/envs/basicFlask/lib/python3.8/site-packages/flask/app.py", line 1950, in full_dispatch_request
    rv = self.dispatch_request()
  File "/Users/park/miniconda3/envs/basicFlask/lib/python3.8/site-packages/flask/app.py", line 1936, in dispatch_request
    return self.view_functions[rule.endpoint](**req.view_args)
  File "/Users/park/SolutionProjects/basicFlask/appConfig/routes.py", line 219, in kakao_callback
    token_json = token_request.json().decode('utf-8')
  File "/Users/park/miniconda3/envs/basicFlask/lib/python3.8/site-packages/requests/models.py", line 900, in json
    return complexjson.loads(self.text, **kwargs)
  File "/Users/park/miniconda3/envs/basicFlask/lib/python3.8/json/__init__.py", line 357, in loads
    return _default_decoder.decode(s)
  File "/Users/park/miniconda3/envs/basicFlask/lib/python3.8/json/decoder.py", line 337, in decode
    obj, end = self.raw_decode(s, idx=_w(s, 0).end())
  File "/Users/park/miniconda3/envs/basicFlask/lib/python3.8/json/decoder.py", line 355, in raw_decode
    raise JSONDecodeError("Expecting value", s, err.value) from None
json.decoder.JSONDecodeError: Expecting value: line 2 column 1 (char 1)
Exception on /oauth/kakao/callback [GET]
Traceback (most recent call last):
  File "/Users/park/miniconda3/envs/basicFlask/lib/python3.8/site-packages/flask/app.py", line 2447, in wsgi_app
    response = self.full_dispatch_request()
  File "/Users/park/miniconda3/envs/basicFlask/lib/python3.8/site-packages/flask/app.py", line 1952, in full_dispatch_request
    rv = self.handle_user_exception(e)
  File "/Users/park/miniconda3/envs/basicFlask/lib/python3.8/site-packages/flask_cors/extension.py", line 165, in wrapped_function
    return cors_after_request(app.make_response(f(*args, **kwargs)))
  File "/Users/park/miniconda3/envs/basicFlask/lib/python3.8/site-packages/flask/app.py", line 1821, in handle_user_exception
    reraise(exc_type, exc_value, tb)
  File "/Users/park/miniconda3/envs/basicFlask/lib/python3.8/site-packages/flask/_compat.py", line 39, in reraise
    raise value
  File "/Users/park/miniconda3/envs/basicFlask/lib/python3.8/site-packages/flask/app.py", line 1950, in full_dispatch_request
    rv = self.dispatch_request()
  File "/Users/park/miniconda3/envs/basicFlask/lib/python3.8/site-packages/flask/app.py", line 1936, in dispatch_request
    return self.view_functions[rule.endpoint](**req.view_args)
  File "/Users/park/SolutionProjects/basicFlask/appConfig/routes.py", line 219, in kakao_callback
    token_json = token_request.json().decode('utf-8')
  File "/Users/park/miniconda3/envs/basicFlask/lib/python3.8/site-packages/requests/models.py", line 900, in json
    return complexjson.loads(self.text, **kwargs)
  File "/Users/park/miniconda3/envs/basicFlask/lib/python3.8/json/__init__.py", line 357, in loads
    return _default_decoder.decode(s)
  File "/Users/park/miniconda3/envs/basicFlask/lib/python3.8/json/decoder.py", line 337, in decode
    obj, end = self.raw_decode(s, idx=_w(s, 0).end())
  File "/Users/park/miniconda3/envs/basicFlask/lib/python3.8/json/decoder.py", line 355, in raw_decode
    raise JSONDecodeError("Expecting value", s, err.value) from None
json.decoder.JSONDecodeError: Expecting value: line 2 column 1 (char 1)
Exception on /oauth/kakao/callback [GET]
Traceback (most recent call last):
  File "/Users/park/miniconda3/envs/basicFlask/lib/python3.8/site-packages/flask/app.py", line 2447, in wsgi_app
    response = self.full_dispatch_request()
  File "/Users/park/miniconda3/envs/basicFlask/lib/python3.8/site-packages/flask/app.py", line 1952, in full_dispatch_request
    rv = self.handle_user_exception(e)
  File "/Users/park/miniconda3/envs/basicFlask/lib/python3.8/site-packages/flask_cors/extension.py", line 165, in wrapped_function
    return cors_after_request(app.make_response(f(*args, **kwargs)))
  File "/Users/park/miniconda3/envs/basicFlask/lib/python3.8/site-packages/flask/app.py", line 1821, in handle_user_exception
    reraise(exc_type, exc_value, tb)
  File "/Users/park/miniconda3/envs/basicFlask/lib/python3.8/site-packages/flask/_compat.py", line 39, in reraise
    raise value
  File "/Users/park/miniconda3/envs/basicFlask/lib/python3.8/site-packages/flask/app.py", line 1950, in full_dispatch_request
    rv = self.dispatch_request()
  File "/Users/park/miniconda3/envs/basicFlask/lib/python3.8/site-packages/flask/app.py", line 1936, in dispatch_request
    return self.view_functions[rule.endpoint](**req.view_args)
  File "/Users/park/SolutionProjects/basicFlask/appConfig/routes.py", line 219, in kakao_callback
    token_json = token_request.json().decode('utf-8')
  File "/Users/park/miniconda3/envs/basicFlask/lib/python3.8/site-packages/requests/models.py", line 900, in json
    return complexjson.loads(self.text, **kwargs)
  File "/Users/park/miniconda3/envs/basicFlask/lib/python3.8/json/__init__.py", line 357, in loads
    return _default_decoder.decode(s)
  File "/Users/park/miniconda3/envs/basicFlask/lib/python3.8/json/decoder.py", line 337, in decode
    obj, end = self.raw_decode(s, idx=_w(s, 0).end())
  File "/Users/park/miniconda3/envs/basicFlask/lib/python3.8/json/decoder.py", line 355, in raw_decode
    raise JSONDecodeError("Expecting value", s, err.value) from None
json.decoder.JSONDecodeError: Expecting value: line 2 column 1 (char 1)
Exception on /oauth/kakao/callback [GET]
Traceback (most recent call last):
  File "/Users/park/miniconda3/envs/basicFlask/lib/python3.8/site-packages/flask/app.py", line 2447, in wsgi_app
    response = self.full_dispatch_request()
  File "/Users/park/miniconda3/envs/basicFlask/lib/python3.8/site-packages/flask/app.py", line 1952, in full_dispatch_request
    rv = self.handle_user_exception(e)
  File "/Users/park/miniconda3/envs/basicFlask/lib/python3.8/site-packages/flask_cors/extension.py", line 165, in wrapped_function
    return cors_after_request(app.make_response(f(*args, **kwargs)))
  File "/Users/park/miniconda3/envs/basicFlask/lib/python3.8/site-packages/flask/app.py", line 1821, in handle_user_exception
    reraise(exc_type, exc_value, tb)
  File "/Users/park/miniconda3/envs/basicFlask/lib/python3.8/site-packages/flask/_compat.py", line 39, in reraise
    raise value
  File "/Users/park/miniconda3/envs/basicFlask/lib/python3.8/site-packages/flask/app.py", line 1950, in full_dispatch_request
    rv = self.dispatch_request()
  File "/Users/park/miniconda3/envs/basicFlask/lib/python3.8/site-packages/flask/app.py", line 1936, in dispatch_request
    return self.view_functions[rule.endpoint](**req.view_args)
  File "/Users/park/SolutionProjects/basicFlask/appConfig/routes.py", line 220, in kakao_callback
    token_json = token_request.json().decode('utf-8')
  File "/Users/park/miniconda3/envs/basicFlask/lib/python3.8/site-packages/requests/models.py", line 900, in json
    return complexjson.loads(self.text, **kwargs)
  File "/Users/park/miniconda3/envs/basicFlask/lib/python3.8/json/__init__.py", line 357, in loads
    return _default_decoder.decode(s)
  File "/Users/park/miniconda3/envs/basicFlask/lib/python3.8/json/decoder.py", line 337, in decode
    obj, end = self.raw_decode(s, idx=_w(s, 0).end())
  File "/Users/park/miniconda3/envs/basicFlask/lib/python3.8/json/decoder.py", line 355, in raw_decode
    raise JSONDecodeError("Expecting value", s, err.value) from None
json.decoder.JSONDecodeError: Expecting value: line 2 column 1 (char 1)
Exception on /oauth/kakao/callback [GET]
Traceback (most recent call last):
  File "/Users/park/miniconda3/envs/basicFlask/lib/python3.8/site-packages/flask/app.py", line 2447, in wsgi_app
    response = self.full_dispatch_request()
  File "/Users/park/miniconda3/envs/basicFlask/lib/python3.8/site-packages/flask/app.py", line 1952, in full_dispatch_request
    rv = self.handle_user_exception(e)
  File "/Users/park/miniconda3/envs/basicFlask/lib/python3.8/site-packages/flask_cors/extension.py", line 165, in wrapped_function
    return cors_after_request(app.make_response(f(*args, **kwargs)))
  File "/Users/park/miniconda3/envs/basicFlask/lib/python3.8/site-packages/flask/app.py", line 1821, in handle_user_exception
    reraise(exc_type, exc_value, tb)
  File "/Users/park/miniconda3/envs/basicFlask/lib/python3.8/site-packages/flask/_compat.py", line 39, in reraise
    raise value
  File "/Users/park/miniconda3/envs/basicFlask/lib/python3.8/site-packages/flask/app.py", line 1950, in full_dispatch_request
    rv = self.dispatch_request()
  File "/Users/park/miniconda3/envs/basicFlask/lib/python3.8/site-packages/flask/app.py", line 1936, in dispatch_request
    return self.view_functions[rule.endpoint](**req.view_args)
  File "/Users/park/SolutionProjects/basicFlask/appConfig/routes.py", line 219, in kakao_callback
    print(token_request.json())
  File "/Users/park/miniconda3/envs/basicFlask/lib/python3.8/site-packages/requests/models.py", line 900, in json
    return complexjson.loads(self.text, **kwargs)
  File "/Users/park/miniconda3/envs/basicFlask/lib/python3.8/json/__init__.py", line 357, in loads
    return _default_decoder.decode(s)
  File "/Users/park/miniconda3/envs/basicFlask/lib/python3.8/json/decoder.py", line 337, in decode
    obj, end = self.raw_decode(s, idx=_w(s, 0).end())
  File "/Users/park/miniconda3/envs/basicFlask/lib/python3.8/json/decoder.py", line 355, in raw_decode
    raise JSONDecodeError("Expecting value", s, err.value) from None
json.decoder.JSONDecodeError: Expecting value: line 2 column 1 (char 1)
Exception on /oauth/kakao/callback [GET]
Traceback (most recent call last):
  File "/Users/park/miniconda3/envs/basicFlask/lib/python3.8/site-packages/flask/app.py", line 2447, in wsgi_app
    response = self.full_dispatch_request()
  File "/Users/park/miniconda3/envs/basicFlask/lib/python3.8/site-packages/flask/app.py", line 1952, in full_dispatch_request
    rv = self.handle_user_exception(e)
  File "/Users/park/miniconda3/envs/basicFlask/lib/python3.8/site-packages/flask_cors/extension.py", line 165, in wrapped_function
    return cors_after_request(app.make_response(f(*args, **kwargs)))
  File "/Users/park/miniconda3/envs/basicFlask/lib/python3.8/site-packages/flask/app.py", line 1821, in handle_user_exception
    reraise(exc_type, exc_value, tb)
  File "/Users/park/miniconda3/envs/basicFlask/lib/python3.8/site-packages/flask/_compat.py", line 39, in reraise
    raise value
  File "/Users/park/miniconda3/envs/basicFlask/lib/python3.8/site-packages/flask/app.py", line 1950, in full_dispatch_request
    rv = self.dispatch_request()
  File "/Users/park/miniconda3/envs/basicFlask/lib/python3.8/site-packages/flask/app.py", line 1936, in dispatch_request
    return self.view_functions[rule.endpoint](**req.view_args)
  File "/Users/park/SolutionProjects/basicFlask/appConfig/routes.py", line 219, in kakao_callback
    token_response = token_request.json()
  File "/Users/park/miniconda3/envs/basicFlask/lib/python3.8/site-packages/requests/models.py", line 900, in json
    return complexjson.loads(self.text, **kwargs)
  File "/Users/park/miniconda3/envs/basicFlask/lib/python3.8/json/__init__.py", line 357, in loads
    return _default_decoder.decode(s)
  File "/Users/park/miniconda3/envs/basicFlask/lib/python3.8/json/decoder.py", line 337, in decode
    obj, end = self.raw_decode(s, idx=_w(s, 0).end())
  File "/Users/park/miniconda3/envs/basicFlask/lib/python3.8/json/decoder.py", line 355, in raw_decode
    raise JSONDecodeError("Expecting value", s, err.value) from None
json.decoder.JSONDecodeError: Expecting value: line 2 column 1 (char 1)
Exception on /oauth/kakao/callback [GET]
Traceback (most recent call last):
  File "/Users/park/miniconda3/envs/basicFlask/lib/python3.8/site-packages/flask/app.py", line 2447, in wsgi_app
    response = self.full_dispatch_request()
  File "/Users/park/miniconda3/envs/basicFlask/lib/python3.8/site-packages/flask/app.py", line 1952, in full_dispatch_request
    rv = self.handle_user_exception(e)
  File "/Users/park/miniconda3/envs/basicFlask/lib/python3.8/site-packages/flask_cors/extension.py", line 165, in wrapped_function
    return cors_after_request(app.make_response(f(*args, **kwargs)))
  File "/Users/park/miniconda3/envs/basicFlask/lib/python3.8/site-packages/flask/app.py", line 1821, in handle_user_exception
    reraise(exc_type, exc_value, tb)
  File "/Users/park/miniconda3/envs/basicFlask/lib/python3.8/site-packages/flask/_compat.py", line 39, in reraise
    raise value
  File "/Users/park/miniconda3/envs/basicFlask/lib/python3.8/site-packages/flask/app.py", line 1950, in full_dispatch_request
    rv = self.dispatch_request()
  File "/Users/park/miniconda3/envs/basicFlask/lib/python3.8/site-packages/flask/app.py", line 1936, in dispatch_request
    return self.view_functions[rule.endpoint](**req.view_args)
  File "/Users/park/SolutionProjects/basicFlask/appConfig/routes.py", line 219, in kakao_callback
    token_response = token_request.json()
  File "/Users/park/miniconda3/envs/basicFlask/lib/python3.8/site-packages/requests/models.py", line 900, in json
    return complexjson.loads(self.text, **kwargs)
  File "/Users/park/miniconda3/envs/basicFlask/lib/python3.8/json/__init__.py", line 357, in loads
    return _default_decoder.decode(s)
  File "/Users/park/miniconda3/envs/basicFlask/lib/python3.8/json/decoder.py", line 337, in decode
    obj, end = self.raw_decode(s, idx=_w(s, 0).end())
  File "/Users/park/miniconda3/envs/basicFlask/lib/python3.8/json/decoder.py", line 355, in raw_decode
    raise JSONDecodeError("Expecting value", s, err.value) from None
json.decoder.JSONDecodeError: Expecting value: line 2 column 1 (char 1)
Exception on /oauth/kakao/callback [GET]
Traceback (most recent call last):
  File "/Users/park/miniconda3/envs/basicFlask/lib/python3.8/site-packages/flask/app.py", line 2447, in wsgi_app
    response = self.full_dispatch_request()
  File "/Users/park/miniconda3/envs/basicFlask/lib/python3.8/site-packages/flask/app.py", line 1952, in full_dispatch_request
    rv = self.handle_user_exception(e)
  File "/Users/park/miniconda3/envs/basicFlask/lib/python3.8/site-packages/flask_cors/extension.py", line 165, in wrapped_function
    return cors_after_request(app.make_response(f(*args, **kwargs)))
  File "/Users/park/miniconda3/envs/basicFlask/lib/python3.8/site-packages/flask/app.py", line 1821, in handle_user_exception
    reraise(exc_type, exc_value, tb)
  File "/Users/park/miniconda3/envs/basicFlask/lib/python3.8/site-packages/flask/_compat.py", line 39, in reraise
    raise value
  File "/Users/park/miniconda3/envs/basicFlask/lib/python3.8/site-packages/flask/app.py", line 1950, in full_dispatch_request
    rv = self.dispatch_request()
  File "/Users/park/miniconda3/envs/basicFlask/lib/python3.8/site-packages/flask/app.py", line 1936, in dispatch_request
    return self.view_functions[rule.endpoint](**req.view_args)
  File "/Users/park/SolutionProjects/basicFlask/appConfig/routes.py", line 219, in kakao_callback
    token_response = token_request.json()
  File "/Users/park/miniconda3/envs/basicFlask/lib/python3.8/site-packages/requests/models.py", line 900, in json
    return complexjson.loads(self.text, **kwargs)
  File "/Users/park/miniconda3/envs/basicFlask/lib/python3.8/json/__init__.py", line 357, in loads
    return _default_decoder.decode(s)
  File "/Users/park/miniconda3/envs/basicFlask/lib/python3.8/json/decoder.py", line 337, in decode
    obj, end = self.raw_decode(s, idx=_w(s, 0).end())
  File "/Users/park/miniconda3/envs/basicFlask/lib/python3.8/json/decoder.py", line 355, in raw_decode
    raise JSONDecodeError("Expecting value", s, err.value) from None
json.decoder.JSONDecodeError: Expecting value: line 2 column 1 (char 1)
Exception on /oauth/kakao/callback [GET]
Traceback (most recent call last):
  File "/Users/park/miniconda3/envs/basicFlask/lib/python3.8/site-packages/flask/app.py", line 2447, in wsgi_app
    response = self.full_dispatch_request()
  File "/Users/park/miniconda3/envs/basicFlask/lib/python3.8/site-packages/flask/app.py", line 1952, in full_dispatch_request
    rv = self.handle_user_exception(e)
  File "/Users/park/miniconda3/envs/basicFlask/lib/python3.8/site-packages/flask_cors/extension.py", line 165, in wrapped_function
    return cors_after_request(app.make_response(f(*args, **kwargs)))
  File "/Users/park/miniconda3/envs/basicFlask/lib/python3.8/site-packages/flask/app.py", line 1821, in handle_user_exception
    reraise(exc_type, exc_value, tb)
  File "/Users/park/miniconda3/envs/basicFlask/lib/python3.8/site-packages/flask/_compat.py", line 39, in reraise
    raise value
  File "/Users/park/miniconda3/envs/basicFlask/lib/python3.8/site-packages/flask/app.py", line 1950, in full_dispatch_request
    rv = self.dispatch_request()
  File "/Users/park/miniconda3/envs/basicFlask/lib/python3.8/site-packages/flask/app.py", line 1936, in dispatch_request
    return self.view_functions[rule.endpoint](**req.view_args)
  File "/Users/park/SolutionProjects/basicFlask/appConfig/routes.py", line 219, in kakao_callback
    token_response = token_request.json()
  File "/Users/park/miniconda3/envs/basicFlask/lib/python3.8/site-packages/requests/models.py", line 900, in json
    return complexjson.loads(self.text, **kwargs)
  File "/Users/park/miniconda3/envs/basicFlask/lib/python3.8/json/__init__.py", line 357, in loads
    return _default_decoder.decode(s)
  File "/Users/park/miniconda3/envs/basicFlask/lib/python3.8/json/decoder.py", line 337, in decode
    obj, end = self.raw_decode(s, idx=_w(s, 0).end())
  File "/Users/park/miniconda3/envs/basicFlask/lib/python3.8/json/decoder.py", line 355, in raw_decode
    raise JSONDecodeError("Expecting value", s, err.value) from None
json.decoder.JSONDecodeError: Expecting value: line 2 column 1 (char 1)
Exception on /oauth/kakao/callback [GET]
Traceback (most recent call last):
  File "/Users/park/miniconda3/envs/basicFlask/lib/python3.8/site-packages/flask/app.py", line 2447, in wsgi_app
    response = self.full_dispatch_request()
  File "/Users/park/miniconda3/envs/basicFlask/lib/python3.8/site-packages/flask/app.py", line 1952, in full_dispatch_request
    rv = self.handle_user_exception(e)
  File "/Users/park/miniconda3/envs/basicFlask/lib/python3.8/site-packages/flask_cors/extension.py", line 165, in wrapped_function
    return cors_after_request(app.make_response(f(*args, **kwargs)))
  File "/Users/park/miniconda3/envs/basicFlask/lib/python3.8/site-packages/flask/app.py", line 1821, in handle_user_exception
    reraise(exc_type, exc_value, tb)
  File "/Users/park/miniconda3/envs/basicFlask/lib/python3.8/site-packages/flask/_compat.py", line 39, in reraise
    raise value
  File "/Users/park/miniconda3/envs/basicFlask/lib/python3.8/site-packages/flask/app.py", line 1950, in full_dispatch_request
    rv = self.dispatch_request()
  File "/Users/park/miniconda3/envs/basicFlask/lib/python3.8/site-packages/flask/app.py", line 1936, in dispatch_request
    return self.view_functions[rule.endpoint](**req.view_args)
  File "/Users/park/SolutionProjects/basicFlask/appConfig/routes.py", line 221, in kakao_callback
    error = token_response.get('error', None)
AttributeError: 'Response' object has no attribute 'get'
Exception on /oauth/kakao/callback [GET]
Traceback (most recent call last):
  File "/Users/park/miniconda3/envs/basicFlask/lib/python3.8/site-packages/flask/app.py", line 2447, in wsgi_app
    response = self.full_dispatch_request()
  File "/Users/park/miniconda3/envs/basicFlask/lib/python3.8/site-packages/flask/app.py", line 1952, in full_dispatch_request
    rv = self.handle_user_exception(e)
  File "/Users/park/miniconda3/envs/basicFlask/lib/python3.8/site-packages/flask_cors/extension.py", line 165, in wrapped_function
    return cors_after_request(app.make_response(f(*args, **kwargs)))
  File "/Users/park/miniconda3/envs/basicFlask/lib/python3.8/site-packages/flask/app.py", line 1821, in handle_user_exception
    reraise(exc_type, exc_value, tb)
  File "/Users/park/miniconda3/envs/basicFlask/lib/python3.8/site-packages/flask/_compat.py", line 39, in reraise
    raise value
  File "/Users/park/miniconda3/envs/basicFlask/lib/python3.8/site-packages/flask/app.py", line 1950, in full_dispatch_request
    rv = self.dispatch_request()
  File "/Users/park/miniconda3/envs/basicFlask/lib/python3.8/site-packages/flask/app.py", line 1936, in dispatch_request
    return self.view_functions[rule.endpoint](**req.view_args)
  File "/Users/park/SolutionProjects/basicFlask/appConfig/routes.py", line 221, in kakao_callback
    error = token_response.get('error', None)
AttributeError: 'Response' object has no attribute 'get'
Exception on /oauth/kakao/callback [GET]
Traceback (most recent call last):
  File "/Users/park/miniconda3/envs/basicFlask/lib/python3.8/site-packages/flask/app.py", line 2447, in wsgi_app
    response = self.full_dispatch_request()
  File "/Users/park/miniconda3/envs/basicFlask/lib/python3.8/site-packages/flask/app.py", line 1952, in full_dispatch_request
    rv = self.handle_user_exception(e)
  File "/Users/park/miniconda3/envs/basicFlask/lib/python3.8/site-packages/flask_cors/extension.py", line 165, in wrapped_function
    return cors_after_request(app.make_response(f(*args, **kwargs)))
  File "/Users/park/miniconda3/envs/basicFlask/lib/python3.8/site-packages/flask/app.py", line 1821, in handle_user_exception
    reraise(exc_type, exc_value, tb)
  File "/Users/park/miniconda3/envs/basicFlask/lib/python3.8/site-packages/flask/_compat.py", line 39, in reraise
    raise value
  File "/Users/park/miniconda3/envs/basicFlask/lib/python3.8/site-packages/flask/app.py", line 1950, in full_dispatch_request
    rv = self.dispatch_request()
  File "/Users/park/miniconda3/envs/basicFlask/lib/python3.8/site-packages/flask/app.py", line 1936, in dispatch_request
    return self.view_functions[rule.endpoint](**req.view_args)
  File "/Users/park/SolutionProjects/basicFlask/appConfig/routes.py", line 220, in kakao_callback
    print(json.loads(token_response.decode('utf-8')))
AttributeError: 'Response' object has no attribute 'decode'
Exception on /oauth/kakao/callback [GET]
Traceback (most recent call last):
  File "/Users/park/miniconda3/envs/basicFlask/lib/python3.8/site-packages/flask/app.py", line 2447, in wsgi_app
    response = self.full_dispatch_request()
  File "/Users/park/miniconda3/envs/basicFlask/lib/python3.8/site-packages/flask/app.py", line 1952, in full_dispatch_request
    rv = self.handle_user_exception(e)
  File "/Users/park/miniconda3/envs/basicFlask/lib/python3.8/site-packages/flask_cors/extension.py", line 165, in wrapped_function
    return cors_after_request(app.make_response(f(*args, **kwargs)))
  File "/Users/park/miniconda3/envs/basicFlask/lib/python3.8/site-packages/flask/app.py", line 1821, in handle_user_exception
    reraise(exc_type, exc_value, tb)
  File "/Users/park/miniconda3/envs/basicFlask/lib/python3.8/site-packages/flask/_compat.py", line 39, in reraise
    raise value
  File "/Users/park/miniconda3/envs/basicFlask/lib/python3.8/site-packages/flask/app.py", line 1950, in full_dispatch_request
    rv = self.dispatch_request()
  File "/Users/park/miniconda3/envs/basicFlask/lib/python3.8/site-packages/flask/app.py", line 1936, in dispatch_request
    return self.view_functions[rule.endpoint](**req.view_args)
  File "/Users/park/SolutionProjects/basicFlask/appConfig/routes.py", line 220, in kakao_callback
    print(json.dumps(token_response))
  File "/Users/park/miniconda3/envs/basicFlask/lib/python3.8/json/__init__.py", line 231, in dumps
    return _default_encoder.encode(obj)
  File "/Users/park/miniconda3/envs/basicFlask/lib/python3.8/json/encoder.py", line 199, in encode
    chunks = self.iterencode(o, _one_shot=True)
  File "/Users/park/miniconda3/envs/basicFlask/lib/python3.8/json/encoder.py", line 257, in iterencode
    return _iterencode(o, 0)
  File "/Users/park/miniconda3/envs/basicFlask/lib/python3.8/json/encoder.py", line 179, in default
    raise TypeError(f'Object of type {o.__class__.__name__} '
TypeError: Object of type Response is not JSON serializable
Exception on /oauth/kakao/callback [GET]
Traceback (most recent call last):
  File "/Users/park/miniconda3/envs/basicFlask/lib/python3.8/site-packages/flask/app.py", line 2447, in wsgi_app
    response = self.full_dispatch_request()
  File "/Users/park/miniconda3/envs/basicFlask/lib/python3.8/site-packages/flask/app.py", line 1952, in full_dispatch_request
    rv = self.handle_user_exception(e)
  File "/Users/park/miniconda3/envs/basicFlask/lib/python3.8/site-packages/flask_cors/extension.py", line 165, in wrapped_function
    return cors_after_request(app.make_response(f(*args, **kwargs)))
  File "/Users/park/miniconda3/envs/basicFlask/lib/python3.8/site-packages/flask/app.py", line 1821, in handle_user_exception
    reraise(exc_type, exc_value, tb)
  File "/Users/park/miniconda3/envs/basicFlask/lib/python3.8/site-packages/flask/_compat.py", line 39, in reraise
    raise value
  File "/Users/park/miniconda3/envs/basicFlask/lib/python3.8/site-packages/flask/app.py", line 1950, in full_dispatch_request
    rv = self.dispatch_request()
  File "/Users/park/miniconda3/envs/basicFlask/lib/python3.8/site-packages/flask/app.py", line 1936, in dispatch_request
    return self.view_functions[rule.endpoint](**req.view_args)
  File "/Users/park/SolutionProjects/basicFlask/appConfig/routes.py", line 220, in kakao_callback
    print(jsonify(token_response))
  File "/Users/park/miniconda3/envs/basicFlask/lib/python3.8/site-packages/flask/json/__init__.py", line 370, in jsonify
    dumps(data, indent=indent, separators=separators) + "\n",
  File "/Users/park/miniconda3/envs/basicFlask/lib/python3.8/site-packages/flask/json/__init__.py", line 211, in dumps
    rv = _json.dumps(obj, **kwargs)
  File "/Users/park/miniconda3/envs/basicFlask/lib/python3.8/json/__init__.py", line 234, in dumps
    return cls(
  File "/Users/park/miniconda3/envs/basicFlask/lib/python3.8/json/encoder.py", line 199, in encode
    chunks = self.iterencode(o, _one_shot=True)
  File "/Users/park/miniconda3/envs/basicFlask/lib/python3.8/json/encoder.py", line 257, in iterencode
    return _iterencode(o, 0)
  File "/Users/park/miniconda3/envs/basicFlask/lib/python3.8/site-packages/flasgger/base.py", line 792, in default
    return super(LazyJSONEncoder, self).default(obj)
  File "/Users/park/miniconda3/envs/basicFlask/lib/python3.8/site-packages/flask/json/__init__.py", line 100, in default
    return _json.JSONEncoder.default(self, o)
  File "/Users/park/miniconda3/envs/basicFlask/lib/python3.8/json/encoder.py", line 179, in default
    raise TypeError(f'Object of type {o.__class__.__name__} '
TypeError: Object of type Response is not JSON serializable
Exception on /oauth/kakao/callback [GET]
Traceback (most recent call last):
  File "/Users/park/miniconda3/envs/basicFlask/lib/python3.8/site-packages/flask/app.py", line 2447, in wsgi_app
    response = self.full_dispatch_request()
  File "/Users/park/miniconda3/envs/basicFlask/lib/python3.8/site-packages/flask/app.py", line 1952, in full_dispatch_request
    rv = self.handle_user_exception(e)
  File "/Users/park/miniconda3/envs/basicFlask/lib/python3.8/site-packages/flask_cors/extension.py", line 165, in wrapped_function
    return cors_after_request(app.make_response(f(*args, **kwargs)))
  File "/Users/park/miniconda3/envs/basicFlask/lib/python3.8/site-packages/flask/app.py", line 1821, in handle_user_exception
    reraise(exc_type, exc_value, tb)
  File "/Users/park/miniconda3/envs/basicFlask/lib/python3.8/site-packages/flask/_compat.py", line 39, in reraise
    raise value
  File "/Users/park/miniconda3/envs/basicFlask/lib/python3.8/site-packages/flask/app.py", line 1950, in full_dispatch_request
    rv = self.dispatch_request()
  File "/Users/park/miniconda3/envs/basicFlask/lib/python3.8/site-packages/flask/app.py", line 1936, in dispatch_request
    return self.view_functions[rule.endpoint](**req.view_args)
  File "/Users/park/SolutionProjects/basicFlask/appConfig/routes.py", line 231, in kakao_callback
    data = json.loads(response.decode('utf-8'))
AttributeError: 'dict' object has no attribute 'decode'
